# Generated by Django 5.1 on 2024-10-05 20:55

import django.contrib.auth.validators
from django.conf import settings
from django.db import migrations, models


class Migration(migrations.Migration):

    dependencies = [
        ('app', '0004_alter_dish_cooks_alter_dish_ingredients'),
    ]

    operations = [
        migrations.AlterField(
            model_name='cook',
            name='first_name',
            field=models.CharField(blank=True, max_length=150, verbose_name='first name'),
        ),
        migrations.AlterField(
            model_name='cook',
            name='last_name',
            field=models.CharField(blank=True, max_length=150, verbose_name='last name'),
        ),
        migrations.AlterField(
            model_name='cook',
            name='username',
            field=models.CharField(error_messages={'unique': 'A user with that username already exists.'}, help_text='Required. 150 characters or fewer. Letters, digits and @/./+/-/_ only.', max_length=150, unique=True, validators=[django.contrib.auth.validators.UnicodeUsernameValidator()], verbose_name='username'),
        ),
        migrations.AlterField(
            model_name='dish',
            name='cooks',
            field=models.ManyToManyField(related_name='dishes', to=settings.AUTH_USER_MODEL),
        ),
    ]
